Workbook

Sheet items_and_content_factor
A1: NA | B1: NA | C1: NA | D1: NA | E1: NA | F1: NA | G1: NA | H1: NA | I1: [g/100g] | J1: [kcal/100g] | K1: [g/100g] | L1: [g/100g] | M1: [mg/100g] | N1: [mg/100g] | O1: [mg/100g] | P1: [µg/100g] | Q1: [mg/100g] | R1: [mg/100g] | S1: [mg/100g] | T1: [mg/100g] | U1: [µg/100g] | V1: RAE | W1: [mg/100g] | X1: [mg/100g] | Y1: [mg/100g] | Z1: [mg/100g] | AA1: [µg/100g] | AB1: [mg/100g] | AC1: [mg/100g] | AD1: [mg/100g] | AE1: [mg/100g] | AF1: [µg/100g] | AG1: [g/100g]
A2: Item Code | B2: Item | C2: Description | D2: HS Code | E2: HS07 Code | F2: HS12 Code | G2: CPC Code | I2: dry_matter | J2: Energy | K2: Protein | L2: Fiber_TD | M2: Zinc | N2: Iron | O2: Calcium | P2: Folate_Tot | Q2: Riboflavin | R2: Choline_Tot | S2: Potassium | T2: Vit_E | U2: Vit_K | V2: Vit_A | W2: Magnesium | X2: Phosphorus | Y2: Copper | Z2: Manganese | AA2: Selenium | AB2: Vit_C | AC2: Thiamin | AD2: Niacin | AE2: Pantothenic_Acid | AF2: Vit_B6 | AG2: PUFAs
A3: 15 | B3: Wheat | C3: Triticum spp.: common (T. aestivum) durum (T. durum) spelt (T. spelta). Common and durum wheat are the main types. Among common wheat, the main varieties are spring and winter, hard and soft, and red and white. At the national level, different varieties should be reported separately, reflecting their different uses. Used mainly for human food. | E3: 100110, 100190 | F3: 100111, 100119, 100191, 100199 | G3: 111 | I3: =VLOOKUP($A3,content_factors_backup!$A$2:$Q$468,I$525,FALSE()) -> 86 | J3: =VLOOKUP($A3,content_factors_backup!$A$2:$Q$468,J$525,FALSE()) -> 341 | K3: =VLOOKUP($A3,content_factors_backup!$A$2:$Q$468,K$525,FALSE()) -> 11.95 | L3: =VLOOKUP($A3,content_factors_backup!$A$2:$Q$468,L$525,FALSE()) -> 2 | M3: =VLOOKUP($A3,content_factors_backup!$A$2:$Q$468,M$525,FALSE()) -> 2.465 | N3: =VLOOKUP($A3,content_factors_backup!$A$2:$Q$468,N$525,FALSE()) -> 4 | O3: =VLOOKUP($A3,content_factors_backup!$A$2:$Q$468,O$525,FALSE()) -> 38.5 | P3: =VLOOKUP($A3,content_factors_backup!$A$2:$Q$468,P$525,FALSE()) -> 40.5 | ... W3: =VLOOKUP($A3,content_factors_backup!$A$2:$Q$468,W$525,FALSE()) -> 0
A4: 16 | B4: Flour, wheat | C4: Defined broadly to include meal, groats and pellets. Strong flours from hard wheat are used for bread, while durum wheat flour is used primarily for pasta. Weaker flours from soft wheat are mainly used in cakes, pastries, biscuits and certain noodles. | E4: 110100, 110311, 110320 | F4: 110100, 110311, 110320 | G4: 23110 | I4: =VLOOKUP($A4,content_factors_backup!$A$2:$Q$468,I$525,FALSE()) -> 88 | J4: =VLOOKUP($A4,content_factors_backup!$A$2:$Q$468,J$525,FALSE()) -> 348 | K4: =VLOOKUP($A4,content_factors_backup!$A$2:$Q$468,K$525,FALSE()) -> 11.4 | L4: =VLOOKUP($A4,content_factors_backup!$A$2:$Q$468,L$525,FALSE()) -> 0.4 | M4: =VLOOKUP($A4,content_factors_backup!$A$2:$Q$468,M$525,FALSE()) -> 1.1 | N4: =VLOOKUP($A4,content_factors_backup!$A$2:$Q$468,N$525,FALSE()) -> 2.2 | O4: =VLOOKUP($A4,content_factors_backup!$A$2:$Q$468,O$525,FALSE()) -> 29.5 | P4: =VLOOKUP($A4,content_factors_backup!$A$2:$Q$468,P$525,FALSE()) -> 25 | ... W4: =VLOOKUP($A4,content_factors_backup!$A$2:$Q$468,W$525,FALSE()) -> 0
A5: 17 | B5: Bran, wheat | C5: Defined broadly to include sharps and other residue from the milling, sifting or other working of the grain. Contains a little flour. | E5: 230230 | F5: 230230 | G5: 39120.01 | I5: =VLOOKUP($A5,content_factors_backup!$A$2:$Q$468,I$525,FALSE()) -> 88.5 | J5: =VLOOKUP($A5,content_factors_backup!$A$2:$Q$468,J$525,FALSE()) -> 216 | K5: =VLOOKUP($A5,content_factors_backup!$A$2:$Q$468,K$525,FALSE()) -> 15.55 | L5: =VLOOKUP($A5,content_factors_backup!$A$2:$Q$468,L$525,FALSE()) -> 42.8 | M5: =VLOOKUP($A5,content_factors_backup!$A$2:$Q$468,M$525,FALSE()) -> 7.27 | N5: =VLOOKUP($A5,content_factors_backup!$A$2:$Q$468,N$525,FALSE()) -> 10.57 | O5: =VLOOKUP($A5,content_factors_backup!$A$2:$Q$468,O$525,FALSE()) -> 73 | P5: =VLOOKUP($A5,content_factors_backup!$A$2:$Q$468,P$525,FALSE()) -> 79 | ... W5: =VLOOKUP($A5,content_factors_backup!$A$2:$Q$468,W$525,FALSE()) -> 0
A6: 18 | B6: Macaroni | C6: Pasta made from semolina, or flour, that is mixed with water and kneaded into a dough. Other ingredients may be included as well. The dough is then shaped into various forms. This heading is limited to macaroni that is not cooked, stuffed or otherwise prepared. | E6: 190211, 190219 | F6: 190211, 190219 | G6: 23710 | I6: =VLOOKUP($A6,content_factors_backup!$A$2:$Q$468,I$525,FALSE()) -> 89.6 | J6: =VLOOKUP($A6,content_factors_backup!$A$2:$Q$468,J$525,FALSE()) -> 124 | K6: =VLOOKUP($A6,content_factors_backup!$A$2:$Q$468,K$525,FALSE()) -> 5.33 | L6: =VLOOKUP($A6,content_factors_backup!$A$2:$Q$468,L$525,FALSE()) -> 2.8 | M6: =VLOOKUP($A6,content_factors_backup!$A$2:$Q$468,M$525,FALSE()) -> 0.81 | N6: =VLOOKUP($A6,content_factors_backup!$A$2:$Q$468,N$525,FALSE()) -> 1.06 | O6: =VLOOKUP($A6,content_factors_backup!$A$2:$Q$468,O$525,FALSE()) -> 15 | P6: =VLOOKUP($A6,content_factors_backup!$A$2:$Q$468,P$525,FALSE()) -> 5 | ... W6: =VLOOKUP($A6,content_factors_backup!$A$2:$Q$468,W$525,FALSE()) -> 0
A7: 20 | B7: Bread | C7: A baked product of flour or meal of cereals, especially wheat. Includes ordinary, unleavened, crackers, rusks, etc. | E7: 190510, 190540, 190590 | F7: 190510, 190540, 190590 | G7: F0020 | I7: =VLOOKUP($A7,content_factors_backup!$A$2:$Q$468,I$525,FALSE()) -> 65 | J7: =VLOOKUP($A7,content_factors_backup!$A$2:$Q$468,J$525,FALSE()) -> 313 | K7: =VLOOKUP($A7,content_factors_backup!$A$2:$Q$468,K$525,FALSE()) -> 12.96 | L7: =VLOOKUP($A7,content_factors_backup!$A$2:$Q$468,L$525,FALSE()) -> 4.7 | M7: =VLOOKUP($A7,content_factors_backup!$A$2:$Q$468,M$525,FALSE()) -> 1.47 | N7: =VLOOKUP($A7,content_factors_backup!$A$2:$Q$468,N$525,FALSE()) -> 4.09 | O7: =VLOOKUP($A7,content_factors_backup!$A$2:$Q$468,O$525,FALSE()) -> 165 | P7: =VLOOKUP($A7,content_factors_backup!$A$2:$Q$468,P$525,FALSE()) -> 86 | ... W7: =VLOOKUP($A7,content_factors_backup!$A$2:$Q$468,W$525,FALSE()) -> 0
A8: 21 | B8: Bulgur | C8: Whole wheat grains that are boiled, dried and cracked, either between stones or in a hand mill. Very popular in the Near East. | E8: 190430 | F8: 190430 | G8: 23140.02 | I8: =VLOOKUP($A8,content_factors_backup!$A$2:$Q$468,I$525,FALSE()) -> 90 | J8: =VLOOKUP($A8,content_factors_backup!$A$2:$Q$468,J$525,FALSE()) -> 83 | K8: =VLOOKUP($A8,content_factors_backup!$A$2:$Q$468,K$525,FALSE()) -> 3.08 | L8: =VLOOKUP($A8,content_factors_backup!$A$2:$Q$468,L$525,FALSE()) -> 4.5 | M8: =VLOOKUP($A8,content_factors_backup!$A$2:$Q$468,M$525,FALSE()) -> 0.57 | N8: =VLOOKUP($A8,content_factors_backup!$A$2:$Q$468,N$525,FALSE()) -> 0.96 | O8: =VLOOKUP($A8,content_factors_backup!$A$2:$Q$468,O$525,FALSE()) -> 10 | P8: =VLOOKUP($A8,content_factors_backup!$A$2:$Q$468,P$525,FALSE()) -> 18 | ... W8: =VLOOKUP($A8,content_factors_backup!$A$2:$Q$468,W$525,FALSE()) -> 0
A9: 22 | B9: Pastry | C9: All baked products excluding those listed under bread. Pastry products may contain ingredients other than wheat flour, such as milk, eggs, sugar, honey, starch, fats, fruit, seeds, etc. | E9: 190520, 190531, 190532, 190540, 190590 | F9: 190520, 190531, 190532, 190540, 190590 | G9: F0022 | I9: =VLOOKUP($A9,content_factors_backup!$A$2:$Q$468,I$525,FALSE()) -> 65 | J9: =VLOOKUP($A9,content_factors_backup!$A$2:$Q$468,J$525,FALSE()) -> 558 | K9: =VLOOKUP($A9,content_factors_backup!$A$2:$Q$468,K$525,FALSE()) -> 7.4 | L9: =VLOOKUP($A9,content_factors_backup!$A$2:$Q$468,L$525,FALSE()) -> 1.5 | M9: =VLOOKUP($A9,content_factors_backup!$A$2:$Q$468,M$525,FALSE()) -> 0.54 | N9: =VLOOKUP($A9,content_factors_backup!$A$2:$Q$468,N$525,FALSE()) -> 2.6 | O9: =VLOOKUP($A9,content_factors_backup!$A$2:$Q$468,O$525,FALSE()) -> 10 | P9: =VLOOKUP($A9,content_factors_backup!$A$2:$Q$468,P$525,FALSE()) -> 55 | ... W9: =VLOOKUP($A9,content_factors_backup!$A$2:$Q$468,W$525,FALSE()) -> 0
A10: 27 | B10: Rice, paddy | C10: Oryza spp., mainly oryza sativa. Rice grain after threshing and winnowing. Also known as rice in the husk and rough rice. Used mainly for human food. | E10: 100610 | F10: 100610 | G10: 113 | I10: =VLOOKUP($A10,content_factors_backup!$A$2:$Q$468,I$525,FALSE()) -> 86 | J10: =VLOOKUP($A10,content_factors_backup!$A$2:$Q$468,J$525,FALSE()) -> 353.4 | K10: =VLOOKUP($A10,content_factors_backup!$A$2:$Q$468,K$525,FALSE()) -> 7.3 | L10: =VLOOKUP($A10,content_factors_backup!$A$2:$Q$468,L$525,FALSE()) -> 0.7 | M10: =VLOOKUP($A10,content_factors_backup!$A$2:$Q$468,M$525,FALSE()) -> 1.4 | N10: =VLOOKUP($A10,content_factors_backup!$A$2:$Q$468,N$525,FALSE()) -> 1.6 | O10: =VLOOKUP($A10,content_factors_backup!$A$2:$Q$468,O$525,FALSE()) -> 12 | P10: =VLOOKUP($A10,content_factors_backup!$A$2:$Q$468,P$525,FALSE()) -> 20 | ... W10: =VLOOKUP($A10,content_factors_backup!$A$2:$Q$468,W$525,FALSE()) -> 0
A11: 28 | B11: Rice, husked | C11: Rice grain without hulls or husks. Also known as brown or cargo rice. | E11: 100620 | F11: 100620 | G11: 23162 | I11: =VLOOKUP($A11,content_factors_backup!$A$2:$Q$468,I$525,FALSE()) -> 0 | J11: =VLOOKUP($A11,content_factors_backup!$A$2:$Q$468,J$525,FALSE()) -> #N/A | K11: =VLOOKUP($A11,content_factors_backup!$A$2:$Q$468,K$525,FALSE()) -> #N/A | L11: =VLOOKUP($A11,content_factors_backup!$A$2:$Q$468,L$525,FALSE()) -> #N/A | M11: =VLOOKUP($A11,content_factors_backup!$A$2:$Q$468,M$525,FALSE()) -> #N/A | N11: =VLOOKUP($A11,content_factors_backup!$A$2:$Q$468,N$525,FALSE()) -> #N/A | O11: =VLOOKUP($A11,content_factors_backup!$A$2:$Q$468,O$525,FALSE()) -> #N/A | P11: =VLOOKUP($A11,content_factors_backup!$A$2:$Q$468,P$525,FALSE()) -> #N/A | ... W11: =VLOOKUP($A11,content_factors_backup!$A$2:$Q$468,W$525,FALSE()) -> #N/A
A12: 30 | B12: Rice - total (Rice milled equivalent) | I12: =VLOOKUP($A12,content_factors_backup!$A$2:$Q$468,I$525,FALSE()) -> 88 | J12: =VLOOKUP($A12,content_factors_backup!$A$2:$Q$468,J$525,FALSE()) -> 353.4 | K12: =VLOOKUP($A12,content_factors_backup!$A$2:$Q$468,K$525,FALSE()) -> 7.3 | L12: =VLOOKUP($A12,content_factors_backup!$A$2:$Q$468,L$525,FALSE()) -> 0.7 | M12: =VLOOKUP($A12,content_factors_backup!$A$2:$Q$468,M$525,FALSE()) -> 1.4 | N12: =VLOOKUP($A12,content_factors_backup!$A$2:$Q$468,N$525,FALSE()) -> 1.6 | O12: =VLOOKUP($A12,content_factors_backup!$A$2:$Q$468,O$525,FALSE()) -> 12 | P12: =VLOOKUP($A12,content_factors_backup!$A$2:$Q$468,P$525,FALSE()) -> 20 | ... W12: =VLOOKUP($A12,content_factors_backup!$A$2:$Q$468,W$525,FALSE()) -> 0
A13: 31 | B13: Rice, milled | C13: White rice milled from locally grown paddy. Includes semi-milled, whole-milled and parboiled rice. | E13: 100630 | F13: 100630 | G13: 23161.02 | I13: =VLOOKUP($A13,content_factors_backup!$A$2:$Q$468,I$525,FALSE()) -> 0 | J13: =VLOOKUP($A13,content_factors_backup!$A$2:$Q$468,J$525,FALSE()) -> #N/A | K13: =VLOOKUP($A13,content_factors_backup!$A$2:$Q$468,K$525,FALSE()) -> #N/A | L13: =VLOOKUP($A13,content_factors_backup!$A$2:$Q$468,L$525,FALSE()) -> #N/A | M13: =VLOOKUP($A13,content_factors_backup!$A$2:$Q$468,M$525,FALSE()) -> #N/A | N13: =VLOOKUP($A13,content_factors_backup!$A$2:$Q$468,N$525,FALSE()) -> #N/A | O13: =VLOOKUP($A13,content_factors_backup!$A$2:$Q$468,O$525,FALSE()) -> #N/A | P13: =VLOOKUP($A13,content_factors_backup!$A$2:$Q$468,P$525,FALSE()) -> #N/A | ... W13: =VLOOKUP($A13,content_factors_backup!$A$2:$Q$468,W$525,FALSE()) -> #N/A
A14: 32 | B14: Rice, broken | C14: Residues from the selection of whole-grain, milled rice. | E14: 100640 | F14: 100640 | G14: 23161.03 | I14: =VLOOKUP($A14,content_factors_backup!$A$2:$Q$468,I$525,FALSE()) -> 0 | J14: =VLOOKUP($A14,content_factors_backup!$A$2:$Q$468,J$525,FALSE()) -> #N/A | K14: =VLOOKUP($A14,content_factors_backup!$A$2:$Q$468,K$525,FALSE()) -> #N/A | L14: =VLOOKUP($A14,content_factors_backup!$A$2:$Q$468,L$525,FALSE()) -> #N/A | M14: =VLOOKUP($A14,content_factors_backup!$A$2:$Q$468,M$525,FALSE()) -> #N/A | N14: =VLOOKUP($A14,content_factors_backup!$A$2:$Q$468,N$525,FALSE()) -> #N/A | O14: =VLOOKUP($A14,content_factors_backup!$A$2:$Q$468,O$525,FALSE()) -> #N/A | P14: =VLOOKUP($A14,content_factors_backup!$A$2:$Q$468,P$525,FALSE()) -> #N/A | ... W14: =VLOOKUP($A14,content_factors_backup!$A$2:$Q$468,W$525,FALSE()) -> #N/A
A15: 36 | B15: Oil, rice bran | C15: Extracted from bran by pressure or, more frequently, by solvents. | E15: 151590 | F15: 151590 | G15: 21691.01 | I15: =VLOOKUP($A15,content_factors_backup!$A$2:$Q$468,I$525,FALSE()) -> 100 | J15: =VLOOKUP($A15,content_factors_backup!$A$2:$Q$468,J$525,FALSE()) -> 900 | K15: =VLOOKUP($A15,content_factors_backup!$A$2:$Q$468,K$525,FALSE()) -> 0 | L15: =VLOOKUP($A15,content_factors_backup!$A$2:$Q$468,L$525,FALSE()) -> 0 | M15: =VLOOKUP($A15,content_factors_backup!$A$2:$Q$468,M$525,FALSE()) -> 0.285 | N15: =VLOOKUP($A15,content_factors_backup!$A$2:$Q$468,N$525,FALSE()) -> 0.235 | O15: =VLOOKUP($A15,content_factors_backup!$A$2:$Q$468,O$525,FALSE()) -> 1 | P15: =VLOOKUP($A15,content_factors_backup!$A$2:$Q$468,P$525,FALSE()) -> 0 | ... W15: =VLOOKUP($A15,content_factors_backup!$A$2:$Q$468,W$525,FALSE()) -> 0
A16: 37 | B16: Cake, rice bran | C16: A residue of the extraction of oil. Also known as de-oiled rice bran. | E16: 230690 | F16: 230690 | G16: 21910.01 | I16: =VLOOKUP($A16,content_factors_backup!$A$2:$Q$468,I$525,FALSE()) -> 90 | J16: =VLOOKUP($A16,content_factors_backup!$A$2:$Q$468,J$525,FALSE()) -> 316 | K16: =VLOOKUP($A16,content_factors_backup!$A$2:$Q$468,K$525,FALSE()) -> 13.35 | L16: =VLOOKUP($A16,content_factors_backup!$A$2:$Q$468,L$525,FALSE()) -> 21 | M16: =VLOOKUP($A16,content_factors_backup!$A$2:$Q$468,M$525,FALSE()) -> 6.04 | N16: =VLOOKUP($A16,content_factors_backup!$A$2:$Q$468,N$525,FALSE()) -> 18.54 | O16: =VLOOKUP($A16,content_factors_backup!$A$2:$Q$468,O$525,FALSE()) -> 57 | P16: =VLOOKUP($A16,content_factors_backup!$A$2:$Q$468,P$525,FALSE()) -> 63 | ... W16: =VLOOKUP($A16,content_factors_backup!$A$2:$Q$468,W$525,FALSE()) -> 0
A17: 38 | B17: Flour, rice | C17: Produced by milling broken or milled rice. Finely ground rice flour is widely used in infant foods and in noodles. It is not used in bread because it lacks the necessary gluten-forming protein. | E17: 110290, 110319, 110320 | F17: 110290, 110319, 110320 | G17: 23120.01 | I17: =VLOOKUP($A17,content_factors_backup!$A$2:$Q$468,I$525,FALSE()) -> 88 | J17: =VLOOKUP($A17,content_factors_backup!$A$2:$Q$468,J$525,FALSE()) -> #N/A | K17: =VLOOKUP($A17,content_factors_backup!$A$2:$Q$468,K$525,FALSE()) -> #N/A | L17: =VLOOKUP($A17,content_factors_backup!$A$2:$Q$468,L$525,FALSE()) -> #N/A | M17: =VLOOKUP($A17,content_factors_backup!$A$2:$Q$468,M$525,FALSE()) -> #N/A | N17: =VLOOKUP($A17,content_factors_backup!$A$2:$Q$468,N$525,FALSE()) -> #N/A | O17: =VLOOKUP($A17,content_factors_backup!$A$2:$Q$468,O$525,FALSE()) -> #N/A | P17: =VLOOKUP($A17,content_factors_backup!$A$2:$Q$468,P$525,FALSE()) -> #N/A | ... W17: =VLOOKUP($A17,content_factors_backup!$A$2:$Q$468,W$525,FALSE()) -> #N/A
A18: 39 | B18: Beverages, fermented rice | C18: Low-alcohol beverages, such as rice wine and sake. | E18: 220600 | F18: 220600 | G18: 24230.02 | I18: =VLOOKUP($A18,content_factors_backup!$A$2:$Q$468,I$525,FALSE()) -> 10 | J18: =VLOOKUP($A18,content_factors_backup!$A$2:$Q$468,J$525,FALSE()) -> 47 | K18: =VLOOKUP($A18,content_factors_backup!$A$2:$Q$468,K$525,FALSE()) -> 0.28 | L18: =VLOOKUP($A18,content_factors_backup!$A$2:$Q$468,L$525,FALSE()) -> 0.3 | M18: =VLOOKUP($A18,content_factors_backup!$A$2:$Q$468,M$525,FALSE()) -> 0.13 | N18: =VLOOKUP($A18,content_factors_backup!$A$2:$Q$468,N$525,FALSE()) -> 0.2 | O18: =VLOOKUP($A18,content_factors_backup!$A$2:$Q$468,O$525,FALSE()) -> 118 | P18: =VLOOKUP($A18,content_factors_backup!$A$2:$Q$468,P$525,FALSE()) -> 2 | ... W18: =VLOOKUP($A18,content_factors_backup!$A$2:$Q$468,W$525,FALSE()) -> 63
A19: 41 | B19: Cereals, breakfast | C19: Foods prepared by swelling and roasting cereals or cereal products, e.g. corn flakes, puffed rice; cereals o/t maize, in grain form, precooked or otherwise prepared. | E19: 190410, 190420, 190490 | F19: 190410, 190420, 190490 | G19: 23140.03 | I19: =VLOOKUP($A19,content_factors_backup!$A$2:$Q$468,I$525,FALSE()) -> 96.5 | J19: =VLOOKUP($A19,content_factors_backup!$A$2:$Q$468,J$525,FALSE()) -> 62 | K19: =VLOOKUP($A19,content_factors_backup!$A$2:$Q$468,K$525,FALSE()) -> 2 | L19: =VLOOKUP($A19,content_factors_backup!$A$2:$Q$468,L$525,FALSE()) -> 1.6 | M19: =VLOOKUP($A19,content_factors_backup!$A$2:$Q$468,M$525,FALSE()) -> 0.48 | N19: =VLOOKUP($A19,content_factors_backup!$A$2:$Q$468,N$525,FALSE()) -> 0.62 | O19: =VLOOKUP($A19,content_factors_backup!$A$2:$Q$468,O$525,FALSE()) -> 7 | P19: =VLOOKUP($A19,content_factors_backup!$A$2:$Q$468,P$525,FALSE()) -> 14 | ... W19: =VLOOKUP($A19,content_factors_backup!$A$2:$Q$468,W$525,FALSE()) -> 0
A20: 44 | B20: Barley | C20: Hordeum spp.: two-row barley (H. disticum) six-row barley (H. hexasticum) four-row barley (H. vulgare). Tolerates poorer soils and lower temperatures better than does wheat. Varieties include with husk and without (naked). Used as a livestock feed, for malt and for preparing foods. The roasted grains are a coffee substitute. | E20: 100300 | F20: 100310, 100390 | G20: 115 | I20: =VLOOKUP($A20,content_factors_backup!$A$2:$Q$468,I$525,FALSE()) -> 86 | J20: =VLOOKUP($A20,content_factors_backup!$A$2:$Q$468,J$525,FALSE()) -> 342 | K20: =VLOOKUP($A20,content_factors_backup!$A$2:$Q$468,K$525,FALSE()) -> 9.85 | L20: =VLOOKUP($A20,content_factors_backup!$A$2:$Q$468,L$525,FALSE()) -> 5.2 | M20: =VLOOKUP($A20,content_factors_backup!$A$2:$Q$468,M$525,FALSE()) -> 2.38 | N20: =VLOOKUP($A20,content_factors_backup!$A$2:$Q$468,N$525,FALSE()) -> 4.5 | O20: =VLOOKUP($A20,content_factors_backup!$A$2:$Q$468,O$525,FALSE()) -> 54.5 | P20: =VLOOKUP($A20,content_factors_backup!$A$2:$Q$468,P$525,FALSE()) -> 21 | ... W20: =VLOOKUP($A20,content_factors_backup!$A$2:$Q$468,W$525,FALSE()) -> 0
A21: 46 | B21: Barley, pearled | C21: Small, round pellets obtained by the further milling of pot barley. This definition also includes kibbled, rolled or flaked grains. | E21: 110419, 110429 | F21: 110419, 110429 | G21: 23140.05 | I21: =VLOOKUP($A21,content_factors_backup!$A$2:$Q$468,I$525,FALSE()) -> 88 | J21: =VLOOKUP($A21,content_factors_backup!$A$2:$Q$468,J$525,FALSE()) -> 123 | K21: =VLOOKUP($A21,content_factors_backup!$A$2:$Q$468,K$525,FALSE()) -> 2.26 | L21: =VLOOKUP($A21,content_factors_backup!$A$2:$Q$468,L$525,FALSE()) -> 3.8 | M21: =VLOOKUP($A21,content_factors_backup!$A$2:$Q$468,M$525,FALSE()) -> 0.82 | N21: =VLOOKUP($A21,content_factors_backup!$A$2:$Q$468,N$525,FALSE()) -> 1.33 | O21: =VLOOKUP($A21,content_factors_backup!$A$2:$Q$468,O$525,FALSE()) -> 11 | P21: =VLOOKUP($A21,content_factors_backup!$A$2:$Q$468,P$525,FALSE()) -> 16 | ... W21: =VLOOKUP($A21,content_factors_backup!$A$2:$Q$468,W$525,FALSE()) -> 0
A22: 49 | B22: Malt | C22: A grain - usually barley - that has been germinated through a soaking process and then dried. Malt is used in brewing and distilling, and as a nutrient additive. Includes whole, ground, flour, and roasted malt, but excludes extracts and preparations. | E22: 110710, 110720 | F22: 110710, 110720 | G22: 24320 | I22: =VLOOKUP($A22,content_factors_backup!$A$2:$Q$468,I$525,FALSE()) -> 95 | J22: =VLOOKUP($A22,content_factors_backup!$A$2:$Q$468,J$525,FALSE()) -> 361 | K22: =VLOOKUP($A22,content_factors_backup!$A$2:$Q$468,K$525,FALSE()) -> 10.28 | L22: =VLOOKUP($A22,content_factors_backup!$A$2:$Q$468,L$525,FALSE()) -> 7.1 | M22: =VLOOKUP($A22,content_factors_backup!$A$2:$Q$468,M$525,FALSE()) -> 2.06 | N22: =VLOOKUP($A22,content_factors_backup!$A$2:$Q$468,N$525,FALSE()) -> 4.71 | O22: =VLOOKUP($A22,content_factors_backup!$A$2:$Q$468,O$525,FALSE()) -> 37 | P22: =VLOOKUP($A22,content_factors_backup!$A$2:$Q$468,P$525,FALSE()) -> 38 | ... W22: =VLOOKUP($A22,content_factors_backup!$A$2:$Q$468,W$525,FALSE()) -> 1
A23: 51 | B23: Beer of barley | C23: Beverage that may be alcoholic or non-alcoholic that is made from fermented malted cereals (mainly barley), water and hops. Non-malted cereals may also be used. The FAO definition differs from the main international classifications in that it includes non-alcoholic beer. | E23: 220300 | F23: 220300 | G23: 24310.01 | I23: =VLOOKUP($A23,content_factors_backup!$A$2:$Q$468,I$525,FALSE()) -> 10 | J23: =VLOOKUP($A23,content_factors_backup!$A$2:$Q$468,J$525,FALSE()) -> 33.5 | K23: =VLOOKUP($A23,content_factors_backup!$A$2:$Q$468,K$525,FALSE()) -> 0.35 | L23: =VLOOKUP($A23,content_factors_backup!$A$2:$Q$468,L$525,FALSE()) -> 0 | M23: =VLOOKUP($A23,content_factors_backup!$A$2:$Q$468,M$525,FALSE()) -> 0.01 | N23: =VLOOKUP($A23,content_factors_backup!$A$2:$Q$468,N$525,FALSE()) -> 0.1 | O23: =VLOOKUP($A23,content_factors_backup!$A$2:$Q$468,O$525,FALSE()) -> 4 | P23: =VLOOKUP($A23,content_factors_backup!$A$2:$Q$468,P$525,FALSE()) -> 5.5 | ... W23: =VLOOKUP($A23,content_factors_backup!$A$2:$Q$468,W$525,FALSE()) -> 0
A24: 56 | B24: Maize | C24: Zea mays Corn, Indian corn, mealies. A grain with a high germ content. At the national level, hybrid and ordinary maize should be reported separately owing to widely different yields and uses. Used largely for animal feed and commercial starch production. | E24: 100510, 100590 | F24: 100510, 100590 | G24: 112 | I24: =VLOOKUP($A24,content_factors_backup!$A$2:$Q$468,I$525,FALSE()) -> 86 | J24: =VLOOKUP($A24,content_factors_backup!$A$2:$Q$468,J$525,FALSE()) -> 353.65 | K24: =VLOOKUP($A24,content_factors_backup!$A$2:$Q$468,K$525,FALSE()) -> 8.6 | L24: =VLOOKUP($A24,content_factors_backup!$A$2:$Q$468,L$525,FALSE()) -> 3 | M24: =VLOOKUP($A24,content_factors_backup!$A$2:$Q$468,M$525,FALSE()) -> 1.7 | N24: =VLOOKUP($A24,content_factors_backup!$A$2:$Q$468,N$525,FALSE()) -> 2.755 | O24: =VLOOKUP($A24,content_factors_backup!$A$2:$Q$468,O$525,FALSE()) -> 10 | P24: =VLOOKUP($A24,content_factors_backup!$A$2:$Q$468,P$525,FALSE()) -> 25.411758 | ... W24: =VLOOKUP($A24,content_factors_backup!$A$2:$Q$468,W$525,FALSE()) -> 1.3333333
A25: 57 | B25: Germ, maize | C25: The seed embryo that is separated during processing and is valued mainly for its oil. | E25: 110430 | F25: 110430 | G25: 23140.06 | I25: =VLOOKUP($A25,content_factors_backup!$A$2:$Q$468,I$525,FALSE()) -> 96 | J25: =VLOOKUP($A25,content_factors_backup!$A$2:$Q$468,J$525,FALSE()) -> 381 | K25: =VLOOKUP($A25,content_factors_backup!$A$2:$Q$468,K$525,FALSE()) -> 0.26 | L25: =VLOOKUP($A25,content_factors_backup!$A$2:$Q$468,L$525,FALSE()) -> 0.9 | M25: =VLOOKUP($A25,content_factors_backup!$A$2:$Q$468,M$525,FALSE()) -> 0.06 | N25: =VLOOKUP($A25,content_factors_backup!$A$2:$Q$468,N$525,FALSE()) -> 0.47 | O25: =VLOOKUP($A25,content_factors_backup!$A$2:$Q$468,O$525,FALSE()) -> 2 | P25: =VLOOKUP($A25,content_factors_backup!$A$2:$Q$468,P$525,FALSE()) -> 0 | ... W25: =VLOOKUP($A25,content_factors_backup!$A$2:$Q$468,W$525,FALSE()) -> 0
A26: 58 | B26: Flour, maize | C26: Broadly defined to include meal, groats and pellets. | E26: 110220, 110313, 110320 | F26: 110220, 110313, 110320 | G26: 23120.03 | I26: =VLOOKUP($A26,content_factors_backup!$A$2:$Q$468,I$525,FALSE()) -> 88 | J26: =VLOOKUP($A26,content_factors_backup!$A$2:$Q$468,J$525,FALSE()) -> 353 | K26: =VLOOKUP($A26,content_factors_backup!$A$2:$Q$468,K$525,FALSE()) -> 8.7 | L26: =VLOOKUP($A26,content_factors_backup!$A$2:$Q$468,L$525,FALSE()) -> 3.4 | M26: =VLOOKUP($A26,content_factors_backup!$A$2:$Q$468,M$525,FALSE()) -> 1.475 | N26: =VLOOKUP($A26,content_factors_backup!$A$2:$Q$468,N$525,FALSE()) -> 2.9 | O26: =VLOOKUP($A26,content_factors_backup!$A$2:$Q$468,O$525,FALSE()) -> 17.5 | P26: =VLOOKUP($A26,content_factors_backup!$A$2:$Q$468,P$525,FALSE()) -> 10 | ... W26: =VLOOKUP($A26,content_factors_backup!$A$2:$Q$468,W$525,FALSE()) -> 0.041666666
A27: 59 | B27: Bran, maize | C27: A by-product of the milling of shelled maize. | E27: 230210 | F27: 230210 | G27: 39120.04 | I27: =VLOOKUP($A27,content_factors_backup!$A$2:$Q$468,I$525,FALSE()) -> 88 | J27: =VLOOKUP($A27,content_factors_backup!$A$2:$Q$468,J$525,FALSE()) -> 224 | K27: =VLOOKUP($A27,content_factors_backup!$A$2:$Q$468,K$525,FALSE()) -> 8.36 | L27: =VLOOKUP($A27,content_factors_backup!$A$2:$Q$468,L$525,FALSE()) -> 79 | M27: =VLOOKUP($A27,content_factors_backup!$A$2:$Q$468,M$525,FALSE()) -> 1.56 | N27: =VLOOKUP($A27,content_factors_backup!$A$2:$Q$468,N$525,FALSE()) -> 2.79 | O27: =VLOOKUP($A27,content_factors_backup!$A$2:$Q$468,O$525,FALSE()) -> 42 | P27: =VLOOKUP($A27,content_factors_backup!$A$2:$Q$468,P$525,FALSE()) -> 4 | ... W27: =VLOOKUP($A27,content_factors_backup!$A$2:$Q$468,W$525,FALSE()) -> 4
A28: 60 | B28: Oil, maize | C28: Extracted from germ by pressure or by solvents. | E28: 151521, 151529 | F28: 151521, 151529 | G28: 21691.02 | I28: =VLOOKUP($A28,content_factors_backup!$A$2:$Q$468,I$525,FALSE()) -> 100 | J28: =VLOOKUP($A28,content_factors_backup!$A$2:$Q$468,J$525,FALSE()) -> 900 | K28: =VLOOKUP($A28,content_factors_backup!$A$2:$Q$468,K$525,FALSE()) -> 0 | L28: =VLOOKUP($A28,content_factors_backup!$A$2:$Q$468,L$525,FALSE()) -> 0 | M28: =VLOOKUP($A28,content_factors_backup!$A$2:$Q$468,M$525,FALSE()) -> 0 | N28: =VLOOKUP($A28,content_factors_backup!$A$2:$Q$468,N$525,FALSE()) -> 0 | O28: =VLOOKUP($A28,content_factors_backup!$A$2:$Q$468,O$525,FALSE()) -> 0 | P28: =VLOOKUP($A28,content_factors_backup!$A$2:$Q$468,P$525,FALSE()) -> 0 | ... W28: =VLOOKUP($A28,content_factors_backup!$A$2:$Q$468,W$525,FALSE()) -> 0
A29: 61 | B29: Cake, maize | C29: A residue of the extraction of oil from germ. | E29: 230690 | F29: 230690 | G29: 21910.02 | I29: =VLOOKUP($A29,content_factors_backup!$A$2:$Q$468,I$525,FALSE()) -> 88 | J29: =VLOOKUP($A29,content_factors_backup!$A$2:$Q$468,J$525,FALSE()) -> 381 | K29: =VLOOKUP($A29,content_factors_backup!$A$2:$Q$468,K$525,FALSE()) -> 0.26 | L29: =VLOOKUP($A29,content_factors_backup!$A$2:$Q$468,L$525,FALSE()) -> 0.9 | M29: =VLOOKUP($A29,content_factors_backup!$A$2:$Q$468,M$525,FALSE()) -> 0.06 | N29: =VLOOKUP($A29,content_factors_backup!$A$2:$Q$468,N$525,FALSE()) -> 0.47 | O29: =VLOOKUP($A29,content_factors_backup!$A$2:$Q$468,O$525,FALSE()) -> 2 | P29: =VLOOKUP($A29,content_factors_backup!$A$2:$Q$468,P$525,FALSE()) -> 0 | ... W29: =VLOOKUP($A29,content_factors_backup!$A$2:$Q$468,W$525,FALSE()) -> 0
A30: 68 | B30: Popcorn | C30: Zea mays var. everta. A variety of maize that is eaten after the kernels have been heated and have "popped". | E30: 100510, 100590 | F30: 100510, 100590 | I30: =VLOOKUP($A30,content_factors_backup!$A$2:$Q$468,I$525,FALSE()) -> #N/A | J30: =VLOOKUP($A30,content_factors_backup!$A$2:$Q$468,J$525,FALSE()) -> #N/A | K30: =VLOOKUP($A30,content_factors_backup!$A$2:$Q$468,K$525,FALSE()) -> #N/A | L30: =VLOOKUP($A30,content_factors_backup!$A$2:$Q$468,L$525,FALSE()) -> #N/A | M30: =VLOOKUP($A30,content_factors_backup!$A$2:$Q$468,M$525,FALSE()) -> #N/A | N30: =VLOOKUP($A30,content_factors_backup!$A$2:$Q$468,N$525,FALSE()) -> #N/A | O30: =VLOOKUP($A30,content_factors_backup!$A$2:$Q$468,O$525,FALSE()) -> #N/A | P30: =VLOOKUP($A30,content_factors_backup!$A$2:$Q$468,P$525,FALSE()) -> #N/A | ... W30: =VLOOKUP($A30,content_factors_backup!$A$2:$Q$468,W$525,FALSE()) -> #N/A
A31: 71 | B31: Rye | C31: Secale cereale. A grain that is tolerant of poor soils, high latitudes and altitudes. Mainly used in making bread, whisky and beer. When fed to livestock, it is generally mixed with other grains. | E31: 100200 | F31: 100210, 100290 | G31: 116 | I31: =VLOOKUP($A31,content_factors_backup!$A$2:$Q$468,I$525,FALSE()) -> 86 | J31: =VLOOKUP($A31,content_factors_backup!$A$2:$Q$468,J$525,FALSE()) -> 338 | K31: =VLOOKUP($A31,content_factors_backup!$A$2:$Q$468,K$525,FALSE()) -> 10.42 | L31: =VLOOKUP($A31,content_factors_backup!$A$2:$Q$468,L$525,FALSE()) -> 2 | M31: =VLOOKUP($A31,content_factors_backup!$A$2:$Q$468,M$525,FALSE()) -> 2.65 | N31: =VLOOKUP($A31,content_factors_backup!$A$2:$Q$468,N$525,FALSE()) -> 2.7 | O31: =VLOOKUP($A31,content_factors_backup!$A$2:$Q$468,O$525,FALSE()) -> 27 | P31: =VLOOKUP($A31,content_factors_backup!$A$2:$Q$468,P$525,FALSE()) -> 38 | ... W31: =VLOOKUP($A31,content_factors_backup!$A$2:$Q$468,W$525,FALSE()) -> 0
A32: 75 | B32: Oats | C32: Avena spp., mainly Avena sativa. A plant with open, spreading panicle-bearing large spikelets. Used primarily in breakfast foods. Makes excellent fodder for horses. | E32: 100400 | F32: 100410, 100490 | G32: 117 | I32: =VLOOKUP($A32,content_factors_backup!$A$2:$Q$468,I$525,FALSE()) -> 86 | J32: =VLOOKUP($A32,content_factors_backup!$A$2:$Q$468,J$525,FALSE()) -> 374 | K32: =VLOOKUP($A32,content_factors_backup!$A$2:$Q$468,K$525,FALSE()) -> 13.45 | L32: =VLOOKUP($A32,content_factors_backup!$A$2:$Q$468,L$525,FALSE()) -> 2.65 | M32: =VLOOKUP($A32,content_factors_backup!$A$2:$Q$468,M$525,FALSE()) -> 3.52 | N32: =VLOOKUP($A32,content_factors_backup!$A$2:$Q$468,N$525,FALSE()) -> 4.46 | O32: =VLOOKUP($A32,content_factors_backup!$A$2:$Q$468,O$525,FALSE()) -> 53 | P32: =VLOOKUP($A32,content_factors_backup!$A$2:$Q$468,P$525,FALSE()) -> 45 | ... W32: =VLOOKUP($A32,content_factors_backup!$A$2:$Q$468,W$525,FALSE()) -> 0
A33: 76 | B33: Oats rolled | C33: Obtained by crushing or rolling the whole or broken grain; includes grains flaked, hulled or otherwise worked for human consumption. | E33: 110412, 110422 | F33: 110412, 110422 | G33: 23140.07 | I33: =VLOOKUP($A33,content_factors_backup!$A$2:$Q$468,I$525,FALSE()) -> 88 | J33: =VLOOKUP($A33,content_factors_backup!$A$2:$Q$468,J$525,FALSE()) -> 374 | K33: =VLOOKUP($A33,content_factors_backup!$A$2:$Q$468,K$525,FALSE()) -> 13.45 | L33: =VLOOKUP($A33,content_factors_backup!$A$2:$Q$468,L$525,FALSE()) -> 2.65 | M33: =VLOOKUP($A33,content_factors_backup!$A$2:$Q$468,M$525,FALSE()) -> 3.52 | N33: =VLOOKUP($A33,content_factors_backup!$A$2:$Q$468,N$525,FALSE()) -> 4.46 | O33: =VLOOKUP($A33,content_factors_backup!$A$2:$Q$468,O$525,FALSE()) -> 53 | P33: =VLOOKUP($A33,content_factors_backup!$A$2:$Q$468,P$525,FALSE()) -> 45 | ... W33: =VLOOKUP($A33,content_factors_backup!$A$2:$Q$468,W$525,FALSE()) -> 0
A34: 79 | B34: Millet | C34: Including inter alia: barnyard or Japanese millet (Echinocloa frumentacea); ragi, finger or African millet (Eleusine coracana); teff (Eragrostis abyssinica); common, golden or proso millet (Panicum miliaceum); koda or ditch millet (Paspalum scrobiculatum); pearl or cattail millet (Pennisetum glaucum); foxtail millet (Setaria italica). Small-grained cereals that include a large number of different botanical species. Originated by the domestication of wild African grasses in the Nile valley and the Sahel zone, millets were subsequently taken to China and India. These cereals tolerate arid conditions and possess a small, highly nutritious grain that stores well. Used locally, both as a food and as a livestock feed. In all areas where they are cultivated, millets are used in traditional beer brewing. Also used as a feed for birds. | E34: 100820 | F34: 100821, 100829 | G34: 118 | I34: =VLOOKUP($A34,content_factors_backup!$A$2:$Q$468,I$525,FALSE()) -> 86 | J34: =VLOOKUP($A34,content_factors_backup!$A$2:$Q$468,J$525,FALSE()) -> 341 | K34: =VLOOKUP($A34,content_factors_backup!$A$2:$Q$468,K$525,FALSE()) -> 9.6 | L34: =VLOOKUP($A34,content_factors_backup!$A$2:$Q$468,L$525,FALSE()) -> 6.15 | M34: =VLOOKUP($A34,content_factors_backup!$A$2:$Q$468,M$525,FALSE()) -> 2.07 | N34: =VLOOKUP($A34,content_factors_backup!$A$2:$Q$468,N$525,FALSE()) -> 7.5 | O34: =VLOOKUP($A34,content_factors_backup!$A$2:$Q$468,O$525,FALSE()) -> 22.5 | P34: =VLOOKUP($A34,content_factors_backup!$A$2:$Q$468,P$525,FALSE()) -> 29.287651 | ... W34: =VLOOKUP($A34,content_factors_backup!$A$2:$Q$468,W$525,FALSE()) -> 0
A35: 81 | B35: Bran, millet | C35: A milling by-product. | E35: 230240 | F35: 230240 | G35: 39120.07 | I35: =VLOOKUP($A35,content_factors_backup!$A$2:$Q$468,I$525,FALSE()) -> 88.5 | J35: =VLOOKUP($A35,content_factors_backup!$A$2:$Q$468,J$525,FALSE()) -> 119 | K35: =VLOOKUP($A35,content_factors_backup!$A$2:$Q$468,K$525,FALSE()) -> 3.51 | L35: =VLOOKUP($A35,content_factors_backup!$A$2:$Q$468,L$525,FALSE()) -> 1.3 | M35: =VLOOKUP($A35,content_factors_backup!$A$2:$Q$468,M$525,FALSE()) -> 0.91 | N35: =VLOOKUP($A35,content_factors_backup!$A$2:$Q$468,N$525,FALSE()) -> 0.63 | O35: =VLOOKUP($A35,content_factors_backup!$A$2:$Q$468,O$525,FALSE()) -> 3 | P35: =VLOOKUP($A35,content_factors_backup!$A$2:$Q$468,P$525,FALSE()) -> 19 | ... W35: =VLOOKUP($A35,content_factors_backup!$A$2:$Q$468,W$525,FALSE()) -> 0
A36: 83 | B36: Sorghum | C36: Sorghum spp.: guinea corn (S. guineense); common, milo, feterita, kaffir corn (S. vulgare); durra, jowar, kaoliang (S. dura). A cereal that has both food and feed uses. Sorghum is a major food grain in most of Africa, where it is also used in traditional beer brewing. It is desirable to report hybrid and other varieties separately. | E36: 100700 | F36: 100710, 100790 | G36: 114 | I36: =VLOOKUP($A36,content_factors_backup!$A$2:$Q$468,I$525,FALSE()) -> 86 | J36: =VLOOKUP($A36,content_factors_backup!$A$2:$Q$468,J$525,FALSE()) -> 348.5 | K36: =VLOOKUP($A36,content_factors_backup!$A$2:$Q$468,K$525,FALSE()) -> 10.7 | L36: =VLOOKUP($A36,content_factors_backup!$A$2:$Q$468,L$525,FALSE()) -> 2 | M36: =VLOOKUP($A36,content_factors_backup!$A$2:$Q$468,M$525,FALSE()) -> 1.8785167 | N36: =VLOOKUP($A36,content_factors_backup!$A$2:$Q$468,N$525,FALSE()) -> 4.5 | O36: =VLOOKUP($A36,content_factors_backup!$A$2:$Q$468,O$525,FALSE()) -> 23 | P36: =VLOOKUP($A36,content_factors_backup!$A$2:$Q$468,P$525,FALSE()) -> 29.286637 | ... W36: =VLOOKUP($A36,content_factors_backup!$A$2:$Q$468,W$525,FALSE()) -> 0.41666667
A37: 85 | B37: Bran, sorghum | C37: A milling by-product. | E37: 230240 | F37: 230240 | G37: 39120.08 | I37: =VLOOKUP($A37,content_factors_backup!$A$2:$Q$468,I$525,FALSE()) -> 88 | J37: =VLOOKUP($A37,content_factors_backup!$A$2:$Q$468,J$525,FALSE()) -> 357 | K37: =VLOOKUP($A37,content_factors_backup!$A$2:$Q$468,K$525,FALSE()) -> 9.53 | L37: =VLOOKUP($A37,content_factors_backup!$A$2:$Q$468,L$525,FALSE()) -> 1.9 | M37: =VLOOKUP($A37,content_factors_backup!$A$2:$Q$468,M$525,FALSE()) -> 0.47 | N37: =VLOOKUP($A37,content_factors_backup!$A$2:$Q$468,N$525,FALSE()) -> 0.97 | O37: =VLOOKUP($A37,content_factors_backup!$A$2:$Q$468,O$525,FALSE()) -> 6 | P37: =VLOOKUP($A37,content_factors_backup!$A$2:$Q$468,P$525,FALSE()) -> 0 | ... W37: =VLOOKUP($A37,content_factors_backup!$A$2:$Q$468,W$525,FALSE()) -> 0
A38: 86 | B38: Beer of sorghum | C38: A traditional beer prepared in African countries in which sorghum is cultivated. It is normally consumed while still fermenting. | E38: 220300 | F38: 220300 | G38: 24310.04 | I38: =VLOOKUP($A38,content_factors_backup!$A$2:$Q$468,I$525,FALSE()) -> #N/A | J38: =VLOOKUP($A38,content_factors_backup!$A$2:$Q$468,J$525,FALSE()) -> #N/A | K38: =VLOOKUP($A38,content_factors_backup!$A$2:$Q$468,K$525,FALSE()) -> #N/A | L38: =VLOOKUP($A38,content_factors_backup!$A$2:$Q$468,L$525,FALSE()) -> #N/A | M38: =VLOOKUP($A38,content_factors_backup!$A$2:$Q$468,M$525,FALSE()) -> #N/A | N38: =VLOOKUP($A38,content_factors_backup!$A$2:$Q$468,N$525,FALSE()) -> #N/A | O38: =VLOOKUP($A38,content_factors_backup!$A$2:$Q$468,O$525,FALSE()) -> #N/A | P38: =VLOOKUP($A38,content_factors_backup!$A$2:$Q$468,P$525,FALSE()) -> #N/A | ... W38: =VLOOKUP($A38,content_factors_backup!$A$2:$Q$468,W$525,FALSE()) -> #N/A
A39: 89 | B39: Buckwheat | C39: Fagopyrum esculentum (Polygonaceae). A minor cereal cultivated primarily in northern regions. Buckwheat is considered a cereal, although it does not belong to the gramineous family. | E39: 100810 | F39: 100810 | G39: 1192 | I39: =VLOOKUP($A39,content_factors_backup!$A$2:$Q$468,I$525,FALSE()) -> 86 | J39: =VLOOKUP($A39,content_factors_backup!$A$2:$Q$468,J$525,FALSE()) -> 330 | K39: =VLOOKUP($A39,content_factors_backup!$A$2:$Q$468,K$525,FALSE()) -> 10 | L39: =VLOOKUP($A39,content_factors_backup!$A$2:$Q$468,L$525,FALSE()) -> 9.3 | M39: =VLOOKUP($A39,content_factors_backup!$A$2:$Q$468,M$525,FALSE()) -> 2.4 | N39: =VLOOKUP($A39,content_factors_backup!$A$2:$Q$468,N$525,FALSE()) -> 5.3 | O39: =VLOOKUP($A39,content_factors_backup!$A$2:$Q$468,O$525,FALSE()) -> 43 | P39: =VLOOKUP($A39,content_factors_backup!$A$2:$Q$468,P$525,FALSE()) -> 30 | ... W39: =VLOOKUP($A39,content_factors_backup!$A$2:$Q$468,W$525,FALSE()) -> 1.5
A40: 91 | B40: Bran, buckwheat | C40: A milling by-product. | E40: 230240 | F40: 230240 | G40: 39120.09 | I40: =VLOOKUP($A40,content_factors_backup!$A$2:$Q$468,I$525,FALSE()) -> 88.5 | J40: =VLOOKUP($A40,content_factors_backup!$A$2:$Q$468,J$525,FALSE()) -> 343 | K40: =VLOOKUP($A40,content_factors_backup!$A$2:$Q$468,K$525,FALSE()) -> 13.25 | L40: =VLOOKUP($A40,content_factors_backup!$A$2:$Q$468,L$525,FALSE()) -> 10 | M40: =VLOOKUP($A40,content_factors_backup!$A$2:$Q$468,M$525,FALSE()) -> 2.4 | N40: =VLOOKUP($A40,content_factors_backup!$A$2:$Q$468,N$525,FALSE()) -> 2.2 | O40: =VLOOKUP($A40,content_factors_backup!$A$2:$Q$468,O$525,FALSE()) -> 18 | P40: =VLOOKUP($A40,content_factors_backup!$A$2:$Q$468,P$525,FALSE()) -> 30 | ... W40: =VLOOKUP($A40,content_factors_backup!$A$2:$Q$468,W$525,FALSE()) -> 0
...

Sheet content_factors_backup
A1: FAO code | B1: FAO name | C1: dry_matter_(g) | D1: Energ_(kcal) | E1: Protein_(g) | F1: Fiber_TD_(g) | G1: Zinc_(mg) | H1: Iron_(mg) | I1: Calcium_(mg) | J1: Folate_Tot_(µg) | K1: Riboflavin_(mg) | L1: Choline_Tot_ (mg) | M1: Potassium_(mg) | N1: Vit_E_(mg) | O1: Vit_B12_(µg) | P1: Vit_K_(µg) | Q1: Vit_A_RAE
A2: 15 | B2: Wheat | C2: 86 | D2: =VLOOKUP($A2,'[2]Sheet 1'!$A$2:$Q$3504,4,FALSE()) -> 341 | E2: =VLOOKUP($A2,'[2]Sheet 1'!$A$2:$Q$3504,5,FALSE()) -> 11.95 | F2: =VLOOKUP($A2,'[2]Sheet 1'!$A$2:$Q$3504,6,FALSE()) -> 2 | G2: =VLOOKUP($A2,'[2]Sheet 1'!$A$2:$Q$3504,7,FALSE()) -> 2.465 | H2: =VLOOKUP($A2,'[2]Sheet 1'!$A$2:$Q$3504,8,FALSE()) -> 4 | I2: =VLOOKUP($A2,'[2]Sheet 1'!$A$2:$Q$3504,9,FALSE()) -> 38.5 | J2: =VLOOKUP($A2,'[2]Sheet 1'!$A$2:$Q$3504,10,FALSE()) -> 40.5 | K2: =VLOOKUP($A2,'[2]Sheet 1'!$A$2:$Q$3504,11,FALSE()) -> 0.16 | L2: =VLOOKUP($A2,'[2]Sheet 1'!$A$2:$Q$3504,12,FALSE()) -> 31.2 | M2: =VLOOKUP($A2,'[2]Sheet 1'!$A$2:$Q$3504,13,FALSE()) -> 349 | N2: =VLOOKUP($A2,'[2]Sheet 1'!$A$2:$Q$3504,14,FALSE()) -> 0.90422724 | O2: =VLOOKUP($A2,'[2]Sheet 1'!$A$2:$Q$3504,15,FALSE()) -> 0.00010562215 | P2: =VLOOKUP($A2,'[2]Sheet 1'!$A$2:$Q$3504,16,FALSE()) -> 2.9854177 | Q2: =VLOOKUP($A2,'[2]Sheet 1'!$A$2:$Q$3504,17,FALSE()) -> 0
A3: 16 | B3: Flour, wheat | C3: 88 | D3: =VLOOKUP($A3,'[2]Sheet 1'!$A$2:$Q$3504,4,FALSE()) -> 348 | E3: =VLOOKUP($A3,'[2]Sheet 1'!$A$2:$Q$3504,5,FALSE()) -> 11.4 | F3: =VLOOKUP($A3,'[2]Sheet 1'!$A$2:$Q$3504,6,FALSE()) -> 0.4 | G3: =VLOOKUP($A3,'[2]Sheet 1'!$A$2:$Q$3504,7,FALSE()) -> 1.1 | H3: =VLOOKUP($A3,'[2]Sheet 1'!$A$2:$Q$3504,8,FALSE()) -> 2.2 | I3: =VLOOKUP($A3,'[2]Sheet 1'!$A$2:$Q$3504,9,FALSE()) -> 29.5 | J3: =VLOOKUP($A3,'[2]Sheet 1'!$A$2:$Q$3504,10,FALSE()) -> 25 | K3: =VLOOKUP($A3,'[2]Sheet 1'!$A$2:$Q$3504,11,FALSE()) -> 0.10333333 | L3: =VLOOKUP($A3,'[2]Sheet 1'!$A$2:$Q$3504,12,FALSE()) -> 10.4 | M3: =VLOOKUP($A3,'[2]Sheet 1'!$A$2:$Q$3504,13,FALSE()) -> 132.5 | N3: =VLOOKUP($A3,'[2]Sheet 1'!$A$2:$Q$3504,14,FALSE()) -> 0.71 | O3: =VLOOKUP($A3,'[2]Sheet 1'!$A$2:$Q$3504,15,FALSE()) -> 0 | P3: =VLOOKUP($A3,'[2]Sheet 1'!$A$2:$Q$3504,16,FALSE()) -> 1.9 | Q3: =VLOOKUP($A3,'[2]Sheet 1'!$A$2:$Q$3504,17,FALSE()) -> 0
A4: 17 | B4: Bran, wheat | C4: 88.5 | D4: =VLOOKUP($A4,'[2]Sheet 1'!$A$2:$Q$3504,4,FALSE()) -> 216 | E4: =VLOOKUP($A4,'[2]Sheet 1'!$A$2:$Q$3504,5,FALSE()) -> 15.55 | F4: =VLOOKUP($A4,'[2]Sheet 1'!$A$2:$Q$3504,6,FALSE()) -> 42.8 | G4: =VLOOKUP($A4,'[2]Sheet 1'!$A$2:$Q$3504,7,FALSE()) -> 7.27 | H4: =VLOOKUP($A4,'[2]Sheet 1'!$A$2:$Q$3504,8,FALSE()) -> 10.57 | I4: =VLOOKUP($A4,'[2]Sheet 1'!$A$2:$Q$3504,9,FALSE()) -> 73 | J4: =VLOOKUP($A4,'[2]Sheet 1'!$A$2:$Q$3504,10,FALSE()) -> 79 | K4: =VLOOKUP($A4,'[2]Sheet 1'!$A$2:$Q$3504,11,FALSE()) -> 0.577 | L4: =VLOOKUP($A4,'[2]Sheet 1'!$A$2:$Q$3504,12,FALSE()) -> 74.4 | M4: =VLOOKUP($A4,'[2]Sheet 1'!$A$2:$Q$3504,13,FALSE()) -> 1182 | N4: =VLOOKUP($A4,'[2]Sheet 1'!$A$2:$Q$3504,14,FALSE()) -> 1.49 | O4: =VLOOKUP($A4,'[2]Sheet 1'!$A$2:$Q$3504,15,FALSE()) -> 0 | P4: =VLOOKUP($A4,'[2]Sheet 1'!$A$2:$Q$3504,16,FALSE()) -> 1.9 | Q4: =VLOOKUP($A4,'[2]Sheet 1'!$A$2:$Q$3504,17,FALSE()) -> 0
A5: 18 | B5: Macaroni | C5: 89.6 | D5: =VLOOKUP($A5,'[2]Sheet 1'!$A$2:$Q$3504,4,FALSE()) -> 124 | E5: =VLOOKUP($A5,'[2]Sheet 1'!$A$2:$Q$3504,5,FALSE()) -> 5.33 | F5: =VLOOKUP($A5,'[2]Sheet 1'!$A$2:$Q$3504,6,FALSE()) -> 2.8 | G5: =VLOOKUP($A5,'[2]Sheet 1'!$A$2:$Q$3504,7,FALSE()) -> 0.81 | H5: =VLOOKUP($A5,'[2]Sheet 1'!$A$2:$Q$3504,8,FALSE()) -> 1.06 | I5: =VLOOKUP($A5,'[2]Sheet 1'!$A$2:$Q$3504,9,FALSE()) -> 15 | J5: =VLOOKUP($A5,'[2]Sheet 1'!$A$2:$Q$3504,10,FALSE()) -> 5 | K5: =VLOOKUP($A5,'[2]Sheet 1'!$A$2:$Q$3504,11,FALSE()) -> 0.045 | L5: =VLOOKUP($A5,'[2]Sheet 1'!$A$2:$Q$3504,12,FALSE()) -> 10.7 | M5: =VLOOKUP($A5,'[2]Sheet 1'!$A$2:$Q$3504,13,FALSE()) -> 44 | N5: =VLOOKUP($A5,'[2]Sheet 1'!$A$2:$Q$3504,14,FALSE()) -> 0.3 | O5: =VLOOKUP($A5,'[2]Sheet 1'!$A$2:$Q$3504,15,FALSE()) -> 0 | P5: =VLOOKUP($A5,'[2]Sheet 1'!$A$2:$Q$3504,16,FALSE()) -> 0.7 | Q5: =VLOOKUP($A5,'[2]Sheet 1'!$A$2:$Q$3504,17,FALSE()) -> 0
A6: 20 | B6: Bread | C6: 65 | D6: =VLOOKUP($A6,'[2]Sheet 1'!$A$2:$Q$3504,4,FALSE()) -> 313 | E6: =VLOOKUP($A6,'[2]Sheet 1'!$A$2:$Q$3504,5,FALSE()) -> 12.96 | F6: =VLOOKUP($A6,'[2]Sheet 1'!$A$2:$Q$3504,6,FALSE()) -> 4.7 | G6: =VLOOKUP($A6,'[2]Sheet 1'!$A$2:$Q$3504,7,FALSE()) -> 1.47 | H6: =VLOOKUP($A6,'[2]Sheet 1'!$A$2:$Q$3504,8,FALSE()) -> 4.09 | I6: =VLOOKUP($A6,'[2]Sheet 1'!$A$2:$Q$3504,9,FALSE()) -> 165 | J6: =VLOOKUP($A6,'[2]Sheet 1'!$A$2:$Q$3504,10,FALSE()) -> 86 | K6: =VLOOKUP($A6,'[2]Sheet 1'!$A$2:$Q$3504,11,FALSE()) -> 0.382 | L6: =VLOOKUP($A6,'[2]Sheet 1'!$A$2:$Q$3504,12,FALSE()) -> 22.1 | M6: =VLOOKUP($A6,'[2]Sheet 1'!$A$2:$Q$3504,13,FALSE()) -> 223 | N6: =VLOOKUP($A6,'[2]Sheet 1'!$A$2:$Q$3504,14,FALSE()) -> 0.24 | O6: =VLOOKUP($A6,'[2]Sheet 1'!$A$2:$Q$3504,15,FALSE()) -> 0 | P6: =VLOOKUP($A6,'[2]Sheet 1'!$A$2:$Q$3504,16,FALSE()) -> 5.7 | Q6: =VLOOKUP($A6,'[2]Sheet 1'!$A$2:$Q$3504,17,FALSE()) -> 0
A7: 21 | B7: Bulgur | C7: 90 | D7: =VLOOKUP($A7,'[2]Sheet 1'!$A$2:$Q$3504,4,FALSE()) -> 83 | E7: =VLOOKUP($A7,'[2]Sheet 1'!$A$2:$Q$3504,5,FALSE()) -> 3.08 | F7: =VLOOKUP($A7,'[2]Sheet 1'!$A$2:$Q$3504,6,FALSE()) -> 4.5 | G7: =VLOOKUP($A7,'[2]Sheet 1'!$A$2:$Q$3504,7,FALSE()) -> 0.57 | H7: =VLOOKUP($A7,'[2]Sheet 1'!$A$2:$Q$3504,8,FALSE()) -> 0.96 | I7: =VLOOKUP($A7,'[2]Sheet 1'!$A$2:$Q$3504,9,FALSE()) -> 10 | J7: =VLOOKUP($A7,'[2]Sheet 1'!$A$2:$Q$3504,10,FALSE()) -> 18 | K7: =VLOOKUP($A7,'[2]Sheet 1'!$A$2:$Q$3504,11,FALSE()) -> 0.028 | L7: =VLOOKUP($A7,'[2]Sheet 1'!$A$2:$Q$3504,12,FALSE()) -> 6.9 | M7: =VLOOKUP($A7,'[2]Sheet 1'!$A$2:$Q$3504,13,FALSE()) -> 68 | N7: =VLOOKUP($A7,'[2]Sheet 1'!$A$2:$Q$3504,14,FALSE()) -> 0.01 | O7: =VLOOKUP($A7,'[2]Sheet 1'!$A$2:$Q$3504,15,FALSE()) -> 0 | P7: =VLOOKUP($A7,'[2]Sheet 1'!$A$2:$Q$3504,16,FALSE()) -> 0.5 | Q7: =VLOOKUP($A7,'[2]Sheet 1'!$A$2:$Q$3504,17,FALSE()) -> 0
A8: 22 | B8: Pastry | C8: 65 | D8: =VLOOKUP($A8,'[2]Sheet 1'!$A$2:$Q$3504,4,FALSE()) -> 558 | E8: =VLOOKUP($A8,'[2]Sheet 1'!$A$2:$Q$3504,5,FALSE()) -> 7.4 | F8: =VLOOKUP($A8,'[2]Sheet 1'!$A$2:$Q$3504,6,FALSE()) -> 1.5 | G8: =VLOOKUP($A8,'[2]Sheet 1'!$A$2:$Q$3504,7,FALSE()) -> 0.54 | H8: =VLOOKUP($A8,'[2]Sheet 1'!$A$2:$Q$3504,8,FALSE()) -> 2.6 | I8: =VLOOKUP($A8,'[2]Sheet 1'!$A$2:$Q$3504,9,FALSE()) -> 10 | J8: =VLOOKUP($A8,'[2]Sheet 1'!$A$2:$Q$3504,10,FALSE()) -> 55 | K8: =VLOOKUP($A8,'[2]Sheet 1'!$A$2:$Q$3504,11,FALSE()) -> 0.258 | L8: =VLOOKUP($A8,'[2]Sheet 1'!$A$2:$Q$3504,12,FALSE()) -> 6.2 | M8: =VLOOKUP($A8,'[2]Sheet 1'!$A$2:$Q$3504,13,FALSE()) -> 62 | N8: =VLOOKUP($A8,'[2]Sheet 1'!$A$2:$Q$3504,14,FALSE()) -> 0.55 | O8: =VLOOKUP($A8,'[2]Sheet 1'!$A$2:$Q$3504,15,FALSE()) -> 0 | P8: =VLOOKUP($A8,'[2]Sheet 1'!$A$2:$Q$3504,16,FALSE()) -> 16.3 | Q8: =VLOOKUP($A8,'[2]Sheet 1'!$A$2:$Q$3504,17,FALSE()) -> 0
A9: 27 | B9: Rice, paddy | C9: 86 | D9: =VLOOKUP($A9,'[2]Sheet 1'!$A$2:$Q$3504,4,FALSE()) -> 353.4 | E9: =VLOOKUP($A9,'[2]Sheet 1'!$A$2:$Q$3504,5,FALSE()) -> 7.3 | F9: =VLOOKUP($A9,'[2]Sheet 1'!$A$2:$Q$3504,6,FALSE()) -> 0.7 | G9: =VLOOKUP($A9,'[2]Sheet 1'!$A$2:$Q$3504,7,FALSE()) -> 1.4 | H9: =VLOOKUP($A9,'[2]Sheet 1'!$A$2:$Q$3504,8,FALSE()) -> 1.6 | I9: =VLOOKUP($A9,'[2]Sheet 1'!$A$2:$Q$3504,9,FALSE()) -> 12 | J9: =VLOOKUP($A9,'[2]Sheet 1'!$A$2:$Q$3504,10,FALSE()) -> 20 | K9: =VLOOKUP($A9,'[2]Sheet 1'!$A$2:$Q$3504,11,FALSE()) -> 0.05 | L9: =VLOOKUP($A9,'[2]Sheet 1'!$A$2:$Q$3504,12,FALSE()) -> 0 | M9: =VLOOKUP($A9,'[2]Sheet 1'!$A$2:$Q$3504,13,FALSE()) -> 91.6 | N9: =VLOOKUP($A9,'[2]Sheet 1'!$A$2:$Q$3504,14,FALSE()) -> 0.04 | O9: =VLOOKUP($A9,'[2]Sheet 1'!$A$2:$Q$3504,15,FALSE()) -> 0 | P9: =VLOOKUP($A9,'[2]Sheet 1'!$A$2:$Q$3504,16,FALSE()) -> 0 | Q9: =VLOOKUP($A9,'[2]Sheet 1'!$A$2:$Q$3504,17,FALSE()) -> 0
A10: 28 | B10: Rice, husked | C10: 0 | D10: =VLOOKUP($A10,'[2]Sheet 1'!$A$2:$Q$3504,4,FALSE()) -> #N/A | E10: =VLOOKUP($A10,'[2]Sheet 1'!$A$2:$Q$3504,5,FALSE()) -> #N/A | F10: =VLOOKUP($A10,'[2]Sheet 1'!$A$2:$Q$3504,6,FALSE()) -> #N/A | G10: =VLOOKUP($A10,'[2]Sheet 1'!$A$2:$Q$3504,7,FALSE()) -> #N/A | H10: =VLOOKUP($A10,'[2]Sheet 1'!$A$2:$Q$3504,8,FALSE()) -> #N/A | I10: =VLOOKUP($A10,'[2]Sheet 1'!$A$2:$Q$3504,9,FALSE()) -> #N/A | J10: =VLOOKUP($A10,'[2]Sheet 1'!$A$2:$Q$3504,10,FALSE()) -> #N/A | K10: =VLOOKUP($A10,'[2]Sheet 1'!$A$2:$Q$3504,11,FALSE()) -> #N/A | L10: =VLOOKUP($A10,'[2]Sheet 1'!$A$2:$Q$3504,12,FALSE()) -> #N/A | M10: =VLOOKUP($A10,'[2]Sheet 1'!$A$2:$Q$3504,13,FALSE()) -> #N/A | N10: =VLOOKUP($A10,'[2]Sheet 1'!$A$2:$Q$3504,14,FALSE()) -> #N/A | O10: =VLOOKUP($A10,'[2]Sheet 1'!$A$2:$Q$3504,15,FALSE()) -> #N/A | P10: =VLOOKUP($A10,'[2]Sheet 1'!$A$2:$Q$3504,16,FALSE()) -> #N/A | Q10: =VLOOKUP($A10,'[2]Sheet 1'!$A$2:$Q$3504,17,FALSE()) -> #N/A
A11: 30 | B11: Rice – total (Rice milled equivalent) | C11: 88 | D11: =VLOOKUP($A11,'[2]Sheet 1'!$A$2:$Q$3504,4,FALSE()) -> 353.4 | E11: =VLOOKUP($A11,'[2]Sheet 1'!$A$2:$Q$3504,5,FALSE()) -> 7.3 | F11: =VLOOKUP($A11,'[2]Sheet 1'!$A$2:$Q$3504,6,FALSE()) -> 0.7 | G11: =VLOOKUP($A11,'[2]Sheet 1'!$A$2:$Q$3504,7,FALSE()) -> 1.4 | H11: =VLOOKUP($A11,'[2]Sheet 1'!$A$2:$Q$3504,8,FALSE()) -> 1.6 | I11: =VLOOKUP($A11,'[2]Sheet 1'!$A$2:$Q$3504,9,FALSE()) -> 12 | J11: =VLOOKUP($A11,'[2]Sheet 1'!$A$2:$Q$3504,10,FALSE()) -> 20 | K11: =VLOOKUP($A11,'[2]Sheet 1'!$A$2:$Q$3504,11,FALSE()) -> 0.05 | L11: =VLOOKUP($A11,'[2]Sheet 1'!$A$2:$Q$3504,12,FALSE()) -> 0 | M11: =VLOOKUP($A11,'[2]Sheet 1'!$A$2:$Q$3504,13,FALSE()) -> 91.6 | N11: =VLOOKUP($A11,'[2]Sheet 1'!$A$2:$Q$3504,14,FALSE()) -> 0.04 | O11: =VLOOKUP($A11,'[2]Sheet 1'!$A$2:$Q$3504,15,FALSE()) -> 0 | P11: =VLOOKUP($A11,'[2]Sheet 1'!$A$2:$Q$3504,16,FALSE()) -> 0 | Q11: =VLOOKUP($A11,'[2]Sheet 1'!$A$2:$Q$3504,17,FALSE()) -> 0
A12: 31 | B12: Rice, milled | C12: 0 | D12: =VLOOKUP($A12,'[2]Sheet 1'!$A$2:$Q$3504,4,FALSE()) -> #N/A | E12: =VLOOKUP($A12,'[2]Sheet 1'!$A$2:$Q$3504,5,FALSE()) -> #N/A | F12: =VLOOKUP($A12,'[2]Sheet 1'!$A$2:$Q$3504,6,FALSE()) -> #N/A | G12: =VLOOKUP($A12,'[2]Sheet 1'!$A$2:$Q$3504,7,FALSE()) -> #N/A | H12: =VLOOKUP($A12,'[2]Sheet 1'!$A$2:$Q$3504,8,FALSE()) -> #N/A | I12: =VLOOKUP($A12,'[2]Sheet 1'!$A$2:$Q$3504,9,FALSE()) -> #N/A | J12: =VLOOKUP($A12,'[2]Sheet 1'!$A$2:$Q$3504,10,FALSE()) -> #N/A | K12: =VLOOKUP($A12,'[2]Sheet 1'!$A$2:$Q$3504,11,FALSE()) -> #N/A | L12: =VLOOKUP($A12,'[2]Sheet 1'!$A$2:$Q$3504,12,FALSE()) -> #N/A | M12: =VLOOKUP($A12,'[2]Sheet 1'!$A$2:$Q$3504,13,FALSE()) -> #N/A | N12: =VLOOKUP($A12,'[2]Sheet 1'!$A$2:$Q$3504,14,FALSE()) -> #N/A | O12: =VLOOKUP($A12,'[2]Sheet 1'!$A$2:$Q$3504,15,FALSE()) -> #N/A | P12: =VLOOKUP($A12,'[2]Sheet 1'!$A$2:$Q$3504,16,FALSE()) -> #N/A | Q12: =VLOOKUP($A12,'[2]Sheet 1'!$A$2:$Q$3504,17,FALSE()) -> #N/A
A13: 32 | B13: Rice, broken | C13: 0 | D13: =VLOOKUP($A13,'[2]Sheet 1'!$A$2:$Q$3504,4,FALSE()) -> #N/A | E13: =VLOOKUP($A13,'[2]Sheet 1'!$A$2:$Q$3504,5,FALSE()) -> #N/A | F13: =VLOOKUP($A13,'[2]Sheet 1'!$A$2:$Q$3504,6,FALSE()) -> #N/A | G13: =VLOOKUP($A13,'[2]Sheet 1'!$A$2:$Q$3504,7,FALSE()) -> #N/A | H13: =VLOOKUP($A13,'[2]Sheet 1'!$A$2:$Q$3504,8,FALSE()) -> #N/A | I13: =VLOOKUP($A13,'[2]Sheet 1'!$A$2:$Q$3504,9,FALSE()) -> #N/A | J13: =VLOOKUP($A13,'[2]Sheet 1'!$A$2:$Q$3504,10,FALSE()) -> #N/A | K13: =VLOOKUP($A13,'[2]Sheet 1'!$A$2:$Q$3504,11,FALSE()) -> #N/A | L13: =VLOOKUP($A13,'[2]Sheet 1'!$A$2:$Q$3504,12,FALSE()) -> #N/A | M13: =VLOOKUP($A13,'[2]Sheet 1'!$A$2:$Q$3504,13,FALSE()) -> #N/A | N13: =VLOOKUP($A13,'[2]Sheet 1'!$A$2:$Q$3504,14,FALSE()) -> #N/A | O13: =VLOOKUP($A13,'[2]Sheet 1'!$A$2:$Q$3504,15,FALSE()) -> #N/A | P13: =VLOOKUP($A13,'[2]Sheet 1'!$A$2:$Q$3504,16,FALSE()) -> #N/A | Q13: =VLOOKUP($A13,'[2]Sheet 1'!$A$2:$Q$3504,17,FALSE()) -> #N/A
... A468: 1296 | B468: Waxes vegetable | C468: 90 | D468: =VLOOKUP($A468,'[2]Sheet 1'!$A$2:$Q$3504,4,FALSE()) -> #N/A | E468: =VLOOKUP($A468,'[2]Sheet 1'!$A$2:$Q$3504,5,FALSE()) -> #N/A | F468: =VLOOKUP($A468,'[2]Sheet 1'!$A$2:$Q$3504,6,FALSE()) -> #N/A | G468: =VLOOKUP($A468,'[2]Sheet 1'!$A$2:$Q$3504,7,FALSE()) -> #N/A | H468: =VLOOKUP($A468,'[2]Sheet 1'!$A$2:$Q$3504,8,FALSE()) -> #N/A | I468: =VLOOKUP($A468,'[2]Sheet 1'!$A$2:$Q$3504,9,FALSE()) -> #N/A | J468: =VLOOKUP($A468,'[2]Sheet 1'!$A$2:$Q$3504,10,FALSE()) -> #N/A | K468: =VLOOKUP($A468,'[2]Sheet 1'!$A$2:$Q$3504,11,FALSE()) -> #N/A | L468: =VLOOKUP($A468,'[2]Sheet 1'!$A$2:$Q$3504,12,FALSE()) -> #N/A | M468: =VLOOKUP($A468,'[2]Sheet 1'!$A$2:$Q$3504,13,FALSE()) -> #N/A | N468: =VLOOKUP($A468,'[2]Sheet 1'!$A$2:$Q$3504,14,FALSE()) -> #N/A | O468: =VLOOKUP($A468,'[2]Sheet 1'!$A$2:$Q$3504,15,FALSE()) -> #N/A | P468: =VLOOKUP($A468,'[2]Sheet 1'!$A$2:$Q$3504,16,FALSE()) -> #N/A | Q468: =VLOOKUP($A468,'[2]Sheet 1'!$A$2:$Q$3504,17,FALSE()) -> #N/A
